Workbook

Sheet CHAIR
A1: INTERVIEW SCORESHEET FOR THE FACULTY INSTRUCTOR I | E1: Interviewer: | F1: DELOSA, JOVELYN G. | G1: Date: | H1: 46196
A3: THEME QUESTIONS (OVER 40)
A4: A. BELIEFS | B4: QUESTIONS | C4: Jhonrey A. Cañete | D4: Remarks/Comments | F4: Remarks/Comments | G4: - | H4: Remarks/Comments
A5: Self-Awareness | B5: Tell us something that is not included in your CV, and tell us how you see yourself five (5) years from now.
A6: Teaching Philosophy | B6: What is your Teaching Philosophy, and how did you/are you going to apply that in your class
B7: Sub-Total | C7: =SUM(C5:C6) -> 0 | E7: =SUM(E5:E6) -> 0 | G7: =SUM(G5:G6) -> 0
A8: B. FLEXIBLE LEARNING | B8: QUESTIONS | C8: =C4 -> Jhonrey A. Cañete | D8: Remarks/Comments | E8: =E4 | F8: Remarks/Comments | G8: =G4 -> - | H8: Remarks/Comments
A9: Considerations | B9: If you were to implement Flexible Learning, what would your considerations be?
B10: Sub-Total | C10: =SUM((C9)) -> 0 | E10: =SUM((E9)) -> 0 | G10: =SUM((G9)) -> 0
A11: C. 21ST CENTURY SKILLS | B11: QUESTIONS | C11: =C4 -> Jhonrey A. Cañete | D11: Remarks/Comments | E11: =E4 | F11: Remarks/Comments | G11: =G4 -> - | H11: Remarks/Comments
A12: Diversity | B12: How will you value diversity in the workplace and in the classroom
A13: Collaboration | B13: Share an experience where you successfully collaborated with stakeholders
A14: Motivation | B14: How will you guide students to achieve their goals?
B15: Sub-Total | C15: =SUM(C12:C14) -> 0 | E15: =SUM(E12:E14) -> 0 | G15: =SUM(G12:G14) -> 0
A16: D. CONTRIBUTION | B16: QUESTIONS | C16: =C11 -> Jhonrey A. Cañete | D16: Remarks/Comments | E16: =E11 | F16: Remarks/Comments | G16: =G11 -> - | H16: Remarks/Comments
A17: Background and experience | B17: (How would your background and experiences strengthen this academic institution)
A18: Stress Management | B18: How do you manage stress in the workplace?)
B19: Sub-Total | C19: =SUM(C17:C18) -> 0 | E19: =SUM(E17:E18) -> 0 | G19: =SUM(G17:G18) -> 0
B20: Total | C20: =SUM(C7,C10,C15,C19) -> 0 | E20: =SUM(E7,E10,E15,E19) -> 0 | G20: =SUM(G7,G10,G15,G19) -> 0
A21: PSYCHOSOCIAL (OVER 25)
B22: CRITERIA | C22: =C16 -> Jhonrey A. Cañete | D22: Remarks/Comments | E22: =E16 | F22: Remarks/Comments | G22: =G16 -> - | H22: Remarks/Comments
A23: PROBITY: | B23: Responds to probing questions with honesty and accuracy
A24: ELOCUTION | B24: Uses a clear voice and correct, precise pronunciation
A25: ARTICULATION: | B25: Expresses answers fluently and coherently
A26: DEMEANOR: | B26: Demonstrates appropriate social and non-verbal behaviors (such as body language and facial expressions)
A27: ATTITUDE: | B27: Shows positive disposition and outlook
B28: Total | C28: =SUM(C23:C27) -> 0 | E28: =SUM(E23:E27) -> 0 | G28: =SUM(G23:G27) -> 0
A29: TEACHING DEMONSTRATION
B30: POINTS | D30: Remarks/Comments | F30: Remarks/Comments | H30: Remarks/Comments
A31: Introduction: | B31: 5 PTS
A32: Learning Outcomes: | B32: 5 PTS
A33: Establishing Rapport | B33: 5 PTS
A34: Mastery of the subject matter | B34: 10 PTS
A35: Utilization of Student-Centered Teaching Strategies | B35: 10 PTS
A36: Use of appropriate technology and assessment Techniques | B36: 10 PTS
A37: Art of Questioning | B37: 5 PTS
A38: Integration of core values | B38: 5 PTS
A39: Communication skills: | B39: 10 PTS
A40: Concluding/Processing Techniques: | B40: 5 PTS
A41: Use of Appropriate Assessment Techniques | B41: 5 PTS
...

Sheet VCHAIR
A1: INTERVIEW SCORESHEET FOR THE FACULTY INSTRUCTOR I | E1: Interviewer: | I1: Date: | J1: =CHAIR!#REF! -> #ERROR!
A3: THEME QUESTIONS (OVER 40)
A4: A. BELIEFS | B4: QUESTIONS | C4: =CHAIR!C4 -> Jhonrey A. Cañete | D4: Remarks/Comments | E4: =CHAIR!E4 | F4: Remarks/Comments | G4: =CHAIR!G4 -> - | H4: Remarks/Comments | I4: =CHAIR!#REF! -> #ERROR! | J4: Remarks/Comments | K4: =CHAIR!#REF! -> #ERROR! | L4: Remarks/Comments
A5: Self-Awareness | B5: Tell us something that is not included in your CV, and tell us how you see yourself five (5) years from now. | C5: 4
A6: Teaching Philosophy | B6: What is your Teaching Philosophy, and how did you/are you going to apply that in your class | C6: 4
B7: Sub-Total | C7: =SUM(C5:C6) -> 8 | E7: =SUM(E5:E6) -> 0 | G7: =SUM(G5:G6) -> 0 | I7: =SUM(I5:I6) -> 0 | K7: =SUM(K5:K6) -> 0
A8: B. FLEXIBLE LEARNING | B8: QUESTIONS | C8: =C4 -> Jhonrey A. Cañete | D8: Remarks/Comments | E8: =E4 | F8: Remarks/Comments | G8: =G4 -> - | H8: Remarks/Comments | I8: =I4 -> #ERROR! | J8: Remarks/Comments | K8: =K4 -> #ERROR! | L8: Remarks/Comments
A9: Considerations | B9: If you were to implement Flexible Learning, what would your considerations be? | C9: 4
B10: Sub-Total | C10: =SUM(C9) -> 4 | E10: =SUM(E9) -> 0 | G10: =SUM(G9) -> 0 | I10: =SUM(I9) -> 0 | K10: =SUM(K9) -> 0
A11: C. 21ST CENTURY SKILLS | B11: QUESTIONS | C11: =C4 -> Jhonrey A. Cañete | D11: Remarks/Comments | E11: =E4 | F11: Remarks/Comments | G11: =G4 -> - | H11: Remarks/Comments | I11: =I4 -> #ERROR! | J11: Remarks/Comments | K11: =K4 -> #ERROR! | L11: Remarks/Comments
A12: Diversity | B12: How will you value diversity in the workplace and in the classroom | C12: 4
A13: Collaboration | B13: Share an experience where you successfully collaborated with stakeholders | C13: 4
A14: Motivation | B14: How will you guide students to achieve their goals? | C14: 4
B15: Sub-Total | C15: =SUM(C12:C14) -> 12 | E15: =SUM(E12:E14) -> 0 | G15: =SUM(G12:G14) -> 0 | I15: =SUM(I12:I14) -> 0 | K15: =SUM(K12:K14) -> 0
A16: D. CONTRIBUTION | B16: QUESTIONS | C16: =C11 -> Jhonrey A. Cañete | D16: Remarks/Comments | E16: =E11 | F16: Remarks/Comments | G16: =G11 -> - | H16: Remarks/Comments | I16: =I11 -> #ERROR! | J16: Remarks/Comments | K16: =K4 -> #ERROR! | L16: Remarks/Comments
A17: Background and experience | B17: (How would your background and experiences strengthen this academic institution) | C17: 4
A18: Stress Management | B18: How do you manage stress in the workplace?) | C18: 4
B19: Sub-Total | C19: =SUM(C17:C18) -> 8 | E19: =SUM(E17:E18) -> 0 | G19: =SUM(G17:G18) -> 0 | I19: =SUM(I17:I18) -> 0 | K19: =SUM(K17:K18) -> 0
B20: Total | C20: =SUM(C7,C10,C15,C19) -> 32 | E20: =SUM(E7,E10,E15,E19) -> 0 | G20: =SUM(G7,G10,G15,G19) -> 0 | I20: =SUM(I7,I10,I15,I19) -> 0 | K20: =SUM(K7,K10,K15,K19) -> 0
A21: PSYCHOSOCIAL (OVER 25)
B22: CRITERIA | C22: =C16 -> Jhonrey A. Cañete | D22: Remarks/Comments | E22: =E16 | F22: Remarks/Comments | G22: =G16 -> - | H22: Remarks/Comments | I22: =I16 -> #ERROR! | J22: Remarks/Comments | K22: =K16 -> #ERROR! | L22: Remarks/Comments
A23: PROBITY: | B23: Responds to probing questions with honesty and accuracy | C23: 4
A24: ELOCUTION | B24: Uses a clear voice and correct, precise pronunciation | C24: 4
A25: ARTICULATION: | B25: Expresses answers fluently and coherently | C25: 4
A26: DEMEANOR: | B26: Demonstrates appropriate social and non-verbal behaviors (such as body language and facial expressions) | C26: 4
A27: ATTITUDE: | B27: Shows positive disposition and outlook | C27: 4
B28: Total | C28: =SUM(C23:C27) -> 20 | E28: =SUM(E23:E27) -> 0 | G28: =SUM(G23:G27) -> 0 | I28: =SUM(I23:I27) -> 0
A29: TEACHING DEMONSTRATION
B30: POINTS | C30: =C22 -> Jhonrey A. Cañete | D30: Remarks/Comments | E30: =E22 | F30: Remarks/Comments | G30: =G22 -> - | H30: Remarks/Comments | I30: =I22 -> #ERROR! | J30: Remarks/Comments | K30: =K22 -> #ERROR! | L30: Remarks/Comments
A31: Introduction: | B31: 5 PTS | C31: 4
A32: Learning Outcomes: | B32: 5 PTS | C32: 4
A33: Establishing Rapport | B33: 5 PTS | C33: 4
A34: Mastery of the subject matter | B34: 10 PTS | C34: 9
A35: Utilization of Student-Centered Teaching Strategies | B35: 10 PTS | C35: 9
A36: Use of appropriate technology and assessment Techniques | B36: 10 PTS | C36: 9
A37: Art of Questioning | B37: 5 PTS | C37: 3
A38: Integration of core values | B38: 5 PTS | C38: 3
A39: Communication skills: | B39: 10 PTS | C39: 9
A40: Concluding/Processing Techniques: | B40: 5 PTS | C40: 4
A41: Use of Appropriate Assessment Techniques | B41: 5 PTS | C41: 4
...

Sheet HRMDO
A1: INTERVIEW SCORESHEET FOR THE FACULTY INSTRUCTOR I | E1: Interviewer: | I1: Date: | J1: =CHAIR!#REF! -> #ERROR! | K1: Date: | L1: =CHAIR!#REF! -> #ERROR!
A3: THEME QUESTIONS (OVER 40)
A4: A. BELIEFS | B4: QUESTIONS | C4: =CHAIR!C4 -> Jhonrey A. Cañete | D4: Remarks/Comments | E4: =CHAIR!E4 | F4: Remarks/Comments | G4: =CHAIR!G4 -> - | H4: Remarks/Comments | I4: =CHAIR!#REF! -> #ERROR! | J4: Remarks/Comments | K4: =CHAIR!#REF! -> #ERROR! | L4: Remarks/Comments
A5: Self-Awareness | B5: Tell us something that is not included in your CV, and tell us how you see yourself five (5) years from now. | C5: 4
A6: Teaching Philosophy | B6: What is your Teaching Philosophy, and how did you/are you going to apply that in your class | C6: 4
B7: Sub-Total | C7: =SUM(C5:C6) -> 8 | E7: =SUM(E5:E6) -> 0 | G7: =SUM(G5:G6) -> 0 | I7: =SUM(I5:I6) -> 0 | K7: =SUM(K5:K6) -> 0
A8: B. FLEXIBLE LEARNING | B8: QUESTIONS | C8: =C4 -> Jhonrey A. Cañete | D8: Remarks/Comments | E8: =E4 | F8: Remarks/Comments | G8: =G4 -> - | H8: Remarks/Comments | I8: =I4 -> #ERROR! | J8: Remarks/Comments | K8: =K4 -> #ERROR! | L8: Remarks/Comments
A9: Considerations | B9: If you were to implement Flexible Learning, what would your considerations be? | C9: 4
B10: Sub-Total | C10: =SUM(C9) -> 4 | E10: =SUM(E9) -> 0 | G10: =SUM(G9) -> 0 | I10: =SUM(I9) -> 0 | K10: =SUM(K9) -> 0
A11: C. 21ST CENTURY SKILLS | B11: QUESTIONS | C11: =C4 -> Jhonrey A. Cañete | D11: Remarks/Comments | E11: =E4 | F11: Remarks/Comments | G11: =G4 -> - | H11: Remarks/Comments | I11: =I4 -> #ERROR! | J11: Remarks/Comments | K11: =K4 -> #ERROR! | L11: Remarks/Comments
A12: Diversity | B12: How will you value diversity in the workplace and in the classroom | C12: 4
A13: Collaboration | B13: Share an experience where you successfully collaborated with stakeholders | C13: 4
A14: Motivation | B14: How will you guide students to achieve their goals? | C14: 4
B15: Sub-Total | C15: =SUM(C12:C14) -> 12 | E15: =SUM(E12:E14) -> 0 | G15: =SUM(G12:G14) -> 0 | I15: =SUM(I12:I14) -> 0 | K15: =SUM(K12:K14) -> 0
A16: D. CONTRIBUTION | B16: QUESTIONS | C16: =C11 -> Jhonrey A. Cañete | D16: Remarks/Comments | E16: =E11 | F16: Remarks/Comments | G16: =G11 -> - | H16: Remarks/Comments | I16: =I11 -> #ERROR! | J16: Remarks/Comments | K16: =K11 -> #ERROR! | L16: Remarks/Comments
A17: Background and experience | B17: (How would your background and experiences strengthen this academic institution) | C17: 4
A18: Stress Management | B18: How do you manage stress in the workplace?) | C18: 4
B19: Sub-Total | C19: =SUM(C17:C18) -> 8 | E19: =SUM(E17:E18) -> 0 | G19: =SUM(G17:G18) -> 0 | I19: =SUM(I17:I18) -> 0 | K19: =SUM(K17:K18) -> 0
B20: Total | C20: =SUM(C7,C10,C15) -> 24 | E20: =SUM(E7,E10,E15) -> 0 | G20: =SUM(G7,G10,G15) -> 0 | I20: =SUM(I7,I10,I15) -> 0 | K20: =SUM(K7,K10,K15) -> 0
A21: PSYCHOSOCIAL (OVER 25)
B22: CRITERIA | C22: =C16 -> Jhonrey A. Cañete | D22: Remarks/Comments | E22: =E16 | F22: Remarks/Comments | G22: =G16 -> - | H22: Remarks/Comments | I22: =I16 -> #ERROR! | J22: Remarks/Comments | K22: =K16 -> #ERROR! | L22: Remarks/Comments
A23: PROBITY: | B23: Responds to probing questions with honesty and accuracy | C23: 4
A24: ELOCUTION | B24: Uses a clear voice and correct, precise pronunciation | C24: 4
A25: ARTICULATION: | B25: Expresses answers fluently and coherently | C25: 4
A26: DEMEANOR: | B26: Demonstrates appropriate social and non-verbal behaviors (such as body language and facial expressions) | C26: 4
A27: ATTITUDE: | B27: Shows positive disposition and outlook | C27: 4
B28: Total | C28: =SUM(C23:C27) -> 20 | E28: =SUM(E23:E27) -> 0 | G28: =SUM(G23:G27) -> 0 | I28: =SUM(I23:I27) -> 0 | K28: =SUM(K23:K27) -> 0
A29: TEACHING DEMONSTRATION
B30: POINTS | C30: =C22 -> Jhonrey A. Cañete | D30: Remarks/Comments | E30: =E22 | F30: Remarks/Comments | G30: =G22 -> - | H30: Remarks/Comments | I30: =I22 -> #ERROR! | J30: Remarks/Comments | K30: =K22 -> #ERROR! | L30: Remarks/Comments
A31: Introduction: | B31: 5 PTS | C31: 5
A32: Learning Outcomes: | B32: 5 PTS | C32: 5
A33: Establishing Rapport | B33: 5 PTS | C33: 5
A34: Mastery of the subject matter | B34: 10 PTS | C34: 8
A35: Utilization of Student-Centered Teaching Strategies | B35: 10 PTS | C35: 8
A36: Use of appropriate technology and assessment Techniques | B36: 10 PTS | C36: 8
A37: Art of Questioning | B37: 5 PTS | C37: 5
A38: Integration of core values | B38: 5 PTS | C38: 5
A39: Communication skills: | B39: 10 PTS | C39: 10
A40: Concluding/Processing Techniques: | B40: 5 PTS | C40: 5
A41: Use of Appropriate Assessment Techniques | B41: 5 PTS | C41: 5
...

Sheet FACASPres
A1: INTERVIEW SCORESHEET FOR THE FACULTY INSTRUCTOR I | E1: Interviewer: | F1: GABINETE, JULIUS S. | I1: Date: | J1: =CHAIR!#REF! -> #ERROR!
A3: THEME QUESTIONS (OVER 40)
A4: A. BELIEFS | B4: QUESTIONS | C4: =CHAIR!C4 -> Jhonrey A. Cañete | D4: Remarks/Comments | E4: =CHAIR!E4 | F4: Remarks/Comments | G4: =CHAIR!G4 -> - | H4: Remarks/Comments | I4: =CHAIR!#REF! -> #ERROR! | J4: Remarks/Comments | K4: =CHAIR!#REF! -> #ERROR! | L4: Remarks/Comments
A5: Self-Awareness | B5: Tell us something that is not included in your CV, and tell us how you see yourself five (5) years from now. | C5: 3
A6: Teaching Philosophy | B6: What is your Teaching Philosophy, and how did you/are you going to apply that in your class | C6: 3
A7: Sub-Total | C7: =SUM(C5:C6) -> 6 | E7: =SUM(E5:E6) -> 0 | G7: =SUM(G5:G6) -> 0 | I7: =SUM(I5:I6) -> 0 | K7: =SUM(K5:K6) -> 0
A8: B. FLEXIBLE LEARNING | B8: QUESTIONS | C8: =C4 -> Jhonrey A. Cañete | D8: Remarks/Comments | E8: =E4 | F8: Remarks/Comments | G8: =G4 -> - | H8: Remarks/Comments | I8: =I4 -> #ERROR! | J8: Remarks/Comments | K8: =K4 -> #ERROR! | L8: Remarks/Comments
A9: Considerations | B9: If you were to implement Flexible Learning, what would your considerations be? | C9: 3
A10: Sub-Total | C10: =SUM(C9) -> 3 | E10: =SUM(E9) -> 0 | G10: =SUM(G9) -> 0 | I10: =SUM(I9) -> 0 | K10: =SUM(K9) -> 0
A11: C. 21ST CENTURY SKILLS | B11: QUESTIONS | C11: =C4 -> Jhonrey A. Cañete | D11: Remarks/Comments | E11: =E4 | F11: Remarks/Comments | G11: =G4 -> - | H11: Remarks/Comments | I11: =I4 -> #ERROR! | J11: Remarks/Comments | K11: =K4 -> #ERROR! | L11: Remarks/Comments
A12: Diversity | B12: How will you value diversity in the workplace and in the classroom | C12: 3
A13: Collaboration | B13: Share an experience where you successfully collaborated with stakeholders | C13: 3
A14: Motivational | B14: How will you guide students to achieve their goals? | C14: 4
A15: Sub-Total | C15: =SUM(C12:C14) -> 10 | E15: =SUM(E12:E14) -> 0 | G15: =SUM(G12:G14) -> 0 | I15: =SUM(I12:I14) -> 0
A16: D. CONTRIBUTION | B16: QUESTIONS | C16: =C4 -> Jhonrey A. Cañete | D16: Remarks/Comments | E16: =E4 | F16: Remarks/Comments | G16: =G4 -> - | H16: Remarks/Comments | I16: =I4 -> #ERROR! | J16: Remarks/Comments | K16: =K4 -> #ERROR! | L16: Remarks/Comments
A17: Background and experience | B17: How would your background and experiences strengthen this academic institution | C17: 3
A18: Stress Management | B18: How do you manage stress in the workplace?
A19: Sub-Total | C19: =SUM(C17:C18) -> 3 | E19: =SUM(E17:E18) -> 0 | G19: =SUM(G17:G18) -> 0 | I19: =SUM(I17:I18) -> 0 | K19: =SUM(K17:K18) -> 0
A20: Total | C20: =SUM(C7,C10,C15,C19) -> 22 | E20: =SUM(E7,E10,E15,E19) -> 0 | G20: =SUM(G7,G10,G15,G19) -> 0 | I20: =SUM(I7,I10,I15,I19) -> 0 | K20: =SUM(K7,K10,K15,K19) -> 0
A21: PSYCHOSOCIAL (OVER 25)
B22: CRITERIA | C22: =C8 -> Jhonrey A. Cañete | D22: Remarks/Comments | E22: =E11 | F22: Remarks/Comments | G22: =G11 -> - | H22: Remarks/Comments | I22: =I11 -> #ERROR! | J22: Remarks/Comments | K22: =K16 -> #ERROR! | L22: Remarks/Comments
A23: PROBITY: | B23: Responds to probing questions with honesty and accuracy | C23: 4
A24: ELOCUTION: | B24: Uses a clear voice and correct, precise pronunciation | C24: 4
A25: ARTICULATION: | B25: Expresses answers fluently and coherently | C25: 4
A26: DEMEANOR: | B26: Demonstrates appropriate social and non-verbal behaviors (such as body language and facial expressions) | C26: 4
A27: ATTITUDE: | B27: Shows positive disposition and outlook | C27: 4
A28: Total | C28: =SUM(C23:C27) -> 20 | E28: =SUM(E23:E27) -> 0 | G28: =SUM(G23:G27) -> 0 | I28: =SUM(I23:I27) -> 0 | K28: =SUM(K23:K27) -> 0
A29: TEACHING DEMONSTRATION
B30: POINTS | C30: =C22 -> Jhonrey A. Cañete | D30: Remarks/Comments | E30: =E22 | F30: Remarks/Comments | G30: =G22 -> - | H30: Remarks/Comments | I30: =I22 -> #ERROR! | J30: Remarks/Comments | K30: =K16 -> #ERROR! | L30: Remarks/Comments
A31: Introduction: | B31: 5 PTS | C31: 3
A32: Learning Outcomes: | B32: 5 PTS | C32: 3
A33: Establishing Rapport | B33: 5 PTS | C33: 3
A34: Mastery of the subject matter | B34: 10 PTS | C34: 8
A35: Utilization of Student-Centered Teaching Strategies | B35: 10 PTS | C35: 7
A36: Use of appropriate technology and assessment Techniques | B36: 10 PTS | C36: 7
A37: Art of Questioning | B37: 5 PTS | C37: 3
A38: Integration of core values | B38: 5 PTS | C38: 3
A39: Communication skills | B39: 10 PTS | C39: 6
A40: Concluding/Processing Techniques: | B40: 5 PTS | C40: 3
A41: Use of Appropriate Assessment Techniques | B41: 5 PTS | C41: 3
...

Sheet ICS HEAD
A1: INTERVIEW SCORESHEET FOR THE FACULTY INSTRUCTOR I | E1: Interviewer: | F1: SHIELA MAE M OROZCO | I1: Date: | J1: =CHAIR!#REF! -> #ERROR!
A3: THEME QUESTIONS (OVER 40)
A4: A. BELIEFS | B4: QUESTIONS | C4: =CHAIR!C4 -> Jhonrey A. Cañete | D4: Remarks/Comments | E4: =CHAIR!E4 | F4: Remarks/Comments | G4: =CHAIR!#REF! -> #ERROR! | H4: Remarks/Comments | I4: =CHAIR!#REF! -> #ERROR! | J4: Remarks/Comments | K4: =CHAIR!#REF! -> #ERROR! | L4: Remarks/Comments
A5: Self-Awareness | B5: Tell us something that is not included in your CV, and tell us how you see yourself five (5) years from now. | C5: 4
A6: Teaching Philosophy | B6: What is your Teaching Philosophy, and how did you/are you going to apply that in your class | C6: 4
A7: Sub-Total | C7: =SUM(C5:C6) -> 8 | E7: =SUM(E5:E6) -> 0 | G7: =SUM(G5:G6) -> 0 | I7: =SUM(I5:I6) -> 0 | K7: =SUM(K5:K6) -> 0
A8: B. FLEXIBLE LEARNING | B8: QUESTIONS | C8: =CHAIR!C8 -> Jhonrey A. Cañete | D8: Remarks/Comments | E8: =E4 | F8: Remarks/Comments | G8: =G4 -> #ERROR! | H8: Remarks/Comments | I8: =I4 -> #ERROR! | J8: Remarks/Comments | K8: =K4 -> #ERROR! | L8: Remarks/Comments
A9: Considerations | B9: If you were to implement Flexible Learning, what would your considerations be? | C9: 5
A10: Sub-Total | C10: =SUM(C9) -> 5 | G10: =SUM(G9) -> 0 | I10: =SUM(I9) -> 0 | K10: =SUM(K9) -> 0
A11: C. 21ST CENTURY SKILLS | B11: QUESTIONS | C11: =C4 -> Jhonrey A. Cañete | D11: Remarks/Comments | E11: =E4 | F11: Remarks/Comments | G11: =G4 -> #ERROR! | H11: Remarks/Comments | I11: =I4 -> #ERROR! | J11: Remarks/Comments | K11: =K4 -> #ERROR! | L11: Remarks/Comments
A12: Diversity | B12: How do you value diversity in the workplace and in the classroom | C12: 4 | D12: connect with the students, respect the culture
A13: Collaboration | B13: Share an experience where you successfully collaborated with stakeholders | C13: 5 | D13: collaborated with the stakeholder, LGU
A14: Motivational | B14: How will you guide students to achieve their goals? | C14: 5 | D14: coached and mentored students in academic competition
A15: Sub-Total | C15: =SUM(C12:C14) -> 14 | E15: =SUM(E12:E14) -> 0 | G15: =SUM(G12:G14) -> 0 | I15: =SUM(I12:I14) -> 0 | K15: =SUM(K12:K14) -> 0
A16: D. CONTRIBUTION | B16: QUESTIONS | C16: =C4 -> Jhonrey A. Cañete | D16: Remarks/Comments | E16: =E4 | F16: Remarks/Comments | G16: =G4 -> #ERROR! | H16: Remarks/Comments | I16: =I4 -> #ERROR! | J16: Remarks/Comments | K16: =K4 -> #ERROR! | L16: Remarks/Comments
A17: Motivational | B17: How would your background and experiences strengthen this academic institution | C17: 4
A18: Stress Management | B18: How do you manage stress in the workplace? | C18: 4
A19: Sub-Total | C19: =SUM(C17:C18) -> 8 | G19: =SUM(G17:G18) -> 0 | I19: =SUM(I17:I18) -> 0 | K19: =SUM(K17:K18) -> 0
A20: Total | C20: =SUM(C7,C10,C15,C19) -> 35 | E20: =SUM(E7,E10,E15,E19) -> 0 | G20: =SUM(G7,G10,G15,G19) -> 0 | I20: =SUM(I7,I10,I15,I19) -> 0 | K20: =SUM(K7,K10,K15,K19) -> 0
A21: PSYCHOSOCIAL (OVER 25)
B22: CRITERIA | C22: =C16 -> Jhonrey A. Cañete | D22: Remarks/Comments | E22: =E16 | F22: Remarks/Comments | G22: =G4 -> #ERROR! | H22: Remarks/Comments | I22: =I4 -> #ERROR! | J22: Remarks/Comments | K22: =K4 -> #ERROR! | L22: Remarks/Comments
A23: PROBITY: | B23: Responds to probing questions with honesty and accuracy | C23: 4
A24: ELOCUTION | B24: Uses a clear voice and correct, precise pronunciation | C24: 4
A25: ARTICULATION: | B25: Expresses answers fluently and coherently | C25: 4
A26: DEMEANOR: | B26: Demonstrates appropriate social and non-verbal behaviors (such as body language and facial expressions) | C26: 4
A27: ATTITUDE: | B27: Shows positive disposition and outlook | C27: 5
A28: Total | C28: =SUM(C23:C27) -> 21 | E28: =SUM(E23:E27) -> 0 | G28: =SUM(G23:G27) -> 0 | I28: =SUM(I23:I27) -> 0 | K28: =SUM(K23:K27) -> 0
A29: TEACHING DEMONSTRATION
B30: POINTS | C30: =C4 -> Jhonrey A. Cañete | D30: Remarks/Comments | E30: =E22 | F30: Remarks/Comments | G30: =G22 -> #ERROR! | H30: Remarks/Comments | I30: =I22 -> #ERROR! | J30: Remarks/Comments | K30: =K22 -> #ERROR! | L30: Remarks/Comments
A31: Introduction: | B31: 5 PTS | C31: 5
A32: Learning Outcomes: | B32: 5 PTS | C32: 4
A33: Establishing Rapport | B33: 5 PTS | C33: 4
A34: Mastery of the subject matter | B34: 10 PTS | C34: 8
A35: Utilization of Student-Centered Teaching Strategies | B35: 10 PTS | C35: 8
A36: Use of appropriate technology and assessment Techniques | B36: 10 PTS | C36: 7
A37: Art of Questioning | B37: 5 PTS | C37: 4
A38: Integration of core values | B38: 5 PTS | C38: 4
A39: Communication skills | B39: 10 PTS | C39: 8
A40: Concluding/Processing Techniques: | B40: 5 PTS | C40: 4
A41: Use of Appropriate Assessment Techniques | B41: 5 PTS | C41: 4
...

Sheet BEI Summary
A1: Northern Bukidnon State College
A2: HUMAN RESOURCE MERIT PROMOTION AND SELECTION BOARD
A4: Summary Scores for the INSTRUCTOR I (COS) - ICS
E6: Date:
C7: PART 1 | D7: PART 2 | E7: PART 3
B8: Applicant | C8: Interview | D8: Psychosocial | E8: Teaching Demo
A9: 1 | B9: =CHAIR!C4 -> Jhonrey A. Cañete | C9: =SUM(VCHAIR!C20,HRMDO!C20,FACASPres!C20,'ICS HEAD'!C20)/4 -> 28.25 | D9: =SUM(VCHAIR!C28,HRMDO!C28,FACASPres!C28,'ICS HEAD'!C28)/4 -> 20.25 | E9: =SUM(VCHAIR!C43,HRMDO!C43,FACASPres!C43,'ICS HEAD'!C43)/4 -> 64.25
A10: 2 | B10: =CHAIR!E4 | C10: =SUM(CHAIR!E20,VCHAIR!E20,HRMDO!E20,FACASPres!E20)/5 -> 0 | D10: =SUM(VCHAIR!E28,HRMDO!E28,FACASPres!E28,'ICS HEAD'!E28)/4 -> 0 | E10: =SUM(VCHAIR!E43,HRMDO!E43,FACASPres!E43,'ICS HEAD'!E43)/5 -> 0

Sheet CAR-ICS
A1: Republic of the Philippines
A2: NORTHERN BUKIDNON STATE COLLEGE
A3: Manolo Fortich, Bukidnon
A5: HUMAN RESOURCE MERIT PROMOTION AND SELECTION BOARD
A6: For Teaching Contract of Service Position
A7: COMPARATIVE ASSESSMENT REPORT
A9: Vacant Position | C9: Instructor I | G9: Education | I9: Master of Science in Information Technology, Master in Information Technology, or any Allied Computing Course
A10: Daily Rate | C10: 1325.68 | G10: Eligibility | I10: None Required
A11: Employment Status | C11: Contract of Service | G11: Training | I11: None Required
A12: Office Assignment | C12: Institute for Computer Science | G12: Experience | I12: Preferably with teaching experience
A14: No. | B14: Name of Applicant | C14: Educ. Qualifications, Experience, Training and Eligibility (70 %) | K14: Teaching Demo (20%) | M14: Interview & Psychosocial) (10%) | O14: TOTAL (100) | P14: RANK
A15: 1 | B15: =CHAIR!C4 -> Jhonrey A. Cañete | C15: - Bachelor of Science in Information Technology, Bukidnon State University - Master in Information Technology, University of Immaculate Conception (Ongoing, 24 units) - Instructor at STI College Valencia (2022-2026) | G15: 70 | K15: ='BEI Summary'!E9/80*20 -> 16.0625 | M15: =SUM('BEI Summary'!C9:D9)/65*10 -> 7.4615385 | O15: =SUM(C15:N15) -> 93.524038 | P15: =_xlfn.RANK.EQ(O15,O15:O16,0) -> 1
A16: 2 | B16: =CHAIR!E4 | K16: =SUM('BEI Summary'!E10/80)*20 -> 0 | M16: =SUM('BEI Summary'!F10)/65*10 -> 0 | O16: =SUM(G16:N16) -> 0 | P16: =_xlfn.RANK.EQ(O16,O15:O16,0) -> 2
A17: 3 | B17: =CHAIR!G4 -> -
A18: 2 | B18: =CHAIR!E30 | C18: *Master of Arts in Secondary Education *Bachelor of Science in Engineering Teachnology Management | G18: =[1]BACKGROUND!F10 -> #ERROR! | K18: =SUM('BEI Summary'!E9/80)*20 -> 16.0625 | M18: =SUM('BEI Summary'!C9:D9)/65*10 -> 7.4615385 | O18: =SUM(G18:N18) -> #ERROR! | P18: =_xlfn.RANK.EQ(O18,$O$18,0) -> #ERROR!
A19: ***nothing follows***
B24: NOREEN FAYE M. ESTA | F24: SHIELA MAE OROZCO, MIT | N24: JULIUS S. GABINETE, DM
B25: HRMO II/ OIC-HRMDO | F25: Department Head, ICS | N25: President, Faculty Association
B26: HRMPSB Member | F26: HRMPSB Member | N26: HRMPSB Member
C30: SHEILA K. MAGLENTE, DM | J30: JOVELYN G. DELOSA, PhD
C31: Associate Professor II | J31: Vice President for Academic Affairs
C32: HRMPSB Vice-Chair | J32: HRMPSB Chair
